Workbook

Sheet README
A1: NexusAI Strategic Pricing Dataset v2.0
A4: Purpose | B4: Robust synthetic B2B SaaS pricing dataset with internally consistent customer, contract, and deal lifecycles.
A5: Observation window | B5: January 2024 through December 2025.
A6: Unit of analysis | B6: One row in Deals_Raw equals one commercial opportunity.
A7: Hierarchy | B7: Customer → Contract → Opportunity.
A8: Lifecycle logic | B8: New Business starts a contract; Renewal continues it; Expansion grows an active contract; Win-back follows churn/lost renewal.
A9: Multiple same-product purchases | B9: Allowed only when Contract_ID or Business_Unit differs.
A10: Customer tenure | B10: Time from Customer_Since to each Deal_Date; not the same as contract length.
A11: Contract length | B11: Length of the specific commercial agreement, recorded per opportunity.
A12: Pricing power | B12: Not pre-scored. It should be inferred from win rate, discount, margin, renewal, and expansion outcomes.
A13: Data status | B13: Synthetic source data, deliberately robust rather than pre-analyzed.

Sheet Customer_Master
A1: Customer Master
A4: Customer_ID | B4: Customer | C4: Industry | D4: Region | E4: Sales_Territory | F4: Company_Size | G4: Strategic_Account | H4: Customer_Since | I4: Health_Score | J4: Current_Relationship_Stage
A5: C0001 | B5: LEG-0001 | C5: Legal | D5: South | E5: South Commercial | F5: SMB | G5: No | H5: 43891 | I5: 63 | J5: Mature
A6: C0002 | B6: LEG-0002 | C6: Legal | D6: South | E6: South Enterprise | F6: Enterprise | G6: Yes | H6: 44958 | I6: 74 | J6: Mature
A7: C0003 | B7: TEC-0003 | C7: Technology | D7: Northeast | E7: Northeast Commercial | F7: SMB | G7: No | H7: 44256 | I7: 87 | J7: Growing
A8: C0004 | B8: FIN-0004 | C8: Financial Services | D8: West | E8: West Commercial | F8: Mid-Market | G8: No | H8: 45383 | I8: 50 | J8: At Risk
A9: C0005 | B9: HEA-0005 | C9: Healthcare | D9: South | E9: South Commercial | F9: Mid-Market | G9: No | H9: 43952 | I9: 66 | J9: Mature
A10: C0006 | B10: LEG-0006 | C10: Legal | D10: West | E10: West Commercial | F10: Mid-Market | G10: No | H10: 45323 | I10: 73 | J10: Mature
A11: C0007 | B11: FIN-0007 | C11: Financial Services | D11: Northeast | E11: Northeast Commercial | F11: Mid-Market | G11: No | H11: 43160 | I11: 47 | J11: At Risk
A12: C0008 | B12: TEC-0008 | C12: Technology | D12: South | E12: South Enterprise | F12: Enterprise | G12: Yes | H12: 45536 | I12: 71 | J12: Mature
A13: C0009 | B13: MAN-0009 | C13: Manufacturing | D13: Midwest | E13: Midwest Commercial | F13: SMB | G13: No | H13: 44682 | I13: 38 | J13: At Risk
A14: C0010 | B14: LEG-0010 | C14: Legal | D14: West | E14: West Commercial | F14: Mid-Market | G14: No | H14: 44348 | I14: 59 | J14: Mature
A15: C0011 | B15: TEC-0011 | C15: Technology | D15: Midwest | E15: Midwest Enterprise | F15: Enterprise | G15: Yes | H15: 44197 | I15: 45 | J15: At Risk
A16: C0012 | B16: TEC-0012 | C16: Technology | D16: Midwest | E16: Midwest Commercial | F16: Mid-Market | G16: No | H16: 44531 | I16: 69 | J16: Mature
... A184: C0180 | B184: TEC-0180 | C184: Technology | D184: West | E184: West Commercial | F184: SMB | G184: No | H184: 43344 | I184: 71 | J184: Mature

Sheet Product_Catalog
A1: Product Catalog
A4: Product | B4: Reference_List_Price | C4: Typical_Cost_Rate | D4: Primary_Value_Driver | E4: Notes
A5: Nexus Insights | B5: 30000 | C5: 0.28 | D5: Research productivity | E5: Pricing power must be derived from actual outcomes
A6: Nexus Analytics | B6: 60000 | C6: 0.31 | D6: Decision analytics | E6: Pricing power must be derived from actual outcomes
A7: Nexus Compliance | B7: 85000 | C7: 0.34 | D7: Risk reduction | E7: Pricing power must be derived from actual outcomes
A8: Nexus AI Assistant | B8: 50000 | C8: 0.38 | D8: Labor automation | E8: Pricing power must be derived from actual outcomes
A9: Nexus Enterprise Suite | B9: 180000 | C9: 0.36 | D9: Integrated platform coverage | E9: Pricing power must be derived from actual outcomes

Sheet Contract_Master
A1: Contract Master
A4: Contract_ID | B4: Customer_ID | C4: Customer | D4: Business_Unit | E4: Product | F4: Contract_Start | G4: Original_Term_Years | H4: Initial_Seats | I4: Original_List_ACV | J4: Current_Status | K4: Lifecycle_Validity
A5: CT00001 | B5: C0001 | C5: LEG-0001 | D5: Sales | E5: Nexus Enterprise Suite | F5: 44551 | G5: 1 | H5: 54 | I5: 140300.39 | J5: Active | K5: Valid by generation rule
A6: CT00002 | B6: C0002 | C6: LEG-0002 | D6: Finance | E6: Nexus Enterprise Suite | F6: 45578 | G6: 1 | H6: 1133 | I6: 448091.47 | J6: Active | K6: Valid by generation rule
A7: CT00003 | B7: C0002 | C7: LEG-0002 | D7: Legal | E7: Nexus Insights | F7: 45175 | G7: 3 | H7: 1509 | I7: 79079.559 | J7: Active | K7: Valid by generation rule
A8: CT00004 | B8: C0003 | C8: TEC-0003 | D8: Legal | E8: Nexus Insights | F8: 44917 | G8: 3 | H8: 20 | I8: 24565.523 | J8: Active | K8: Valid by generation rule
A9: CT00005 | B9: C0004 | C9: FIN-0004 | D9: Finance | E9: Nexus AI Assistant | F9: 45567 | G9: 3 | H9: 176 | I9: 64148.04 | J9: Active | K9: Valid by generation rule
A10: CT00006 | B10: C0004 | C10: FIN-0004 | D10: Legal | E10: Nexus Enterprise Suite | F10: 45821 | G10: 1 | H10: 141 | I10: 223858.23 | J10: Active | K10: Valid by generation rule
A11: CT00007 | B11: C0005 | C11: HEA-0005 | D11: Technology | E11: Nexus Enterprise Suite | F11: 44568 | G11: 3 | H11: 276 | I11: 320385.64 | J11: Churned | K11: Valid by generation rule
A12: CT00008 | B12: C0005 | C12: HEA-0005 | D12: Legal | E12: Nexus Enterprise Suite | F12: 45804 | G12: 1 | H12: 110 | I12: 320597.41 | J12: Lost | K12: Valid by generation rule
A13: CT00009 | B13: C0005 | C13: HEA-0005 | D13: Finance | E13: Nexus AI Assistant | F13: 44975 | G13: 1 | H13: 99 | I13: 103727.12 | J13: Churned | K13: Valid by generation rule
A14: CT00010 | B14: C0005 | C14: HEA-0005 | D14: Legal | E14: Nexus Compliance | F14: 44702 | G14: 1 | H14: 209 | I14: 98450.21 | J14: Active | K14: Valid by generation rule
A15: CT00011 | B15: C0006 | C15: LEG-0006 | D15: Legal | E15: Nexus Compliance | F15: 45344 | G15: 1 | H15: 131 | I15: 184726.34 | J15: Lost | K15: Valid by generation rule
A16: CT00012 | B16: C0006 | C16: LEG-0006 | D16: Finance | E16: Nexus Enterprise Suite | F16: 45685 | G16: 1 | H16: 210 | I16: 259121.64 | J16: Lost | K16: Valid by generation rule
... A402: CT00398 | B402: C0180 | C402: TEC-0180 | D402: Legal | E402: Nexus Analytics | F402: 45831 | G402: 1 | H402: 65 | I402: 56101.806 | J402: Lost | K402: Valid by generation rule

Sheet Deals_Raw
A1: Deals_Raw — Salesforce-Style Opportunity Export
A4: Deal_ID | B4: Deal_Date | C4: Customer_ID | D4: Customer | E4: Contract_ID | F4: Business_Unit | G4: Industry | H4: Region | I4: Sales_Territory | J4: Company_Size | K4: Strategic_Account | L4: Customer_Since | M4: Health_Score | N4: Product | O4: Deal_Type | P4: Expansion_Type | Q4: Contract_Years | R4: Seats | S4: Sales_Rep | T4: List_ACV | U4: List_TCV | V4: Discount_Requested | W4: Discount_Approved | X4: Competitor_Gap_vs_Us | Y4: Discount_Reason | Z4: Approval_Level | AA4: Final_Price_ACV | AB4: Final_Price_TCV | AC4: Cost_to_Serve | AD4: Proposed_Gross_Profit | AE4: Proposed_Gross_Margin | AF4: Deal_Status | AG4: Renewed | AH4: Expanded | AI4: Winback_Flag | AJ4: Realized_Revenue | AK4: Realized_Gross_Profit | AL4: Lifecycle_Notes | AM4: Validated_Annual_Final_Price | AN4: Validated_Total_Final_Price2 | AO4: Validated_Grossprofit | AP4: Validated_GrossMargin | AQ4: updated Validated_Annual_Final_Price | AR4: updated Validated_Total_Final_Price2 | AS4: updated Validated_Grossprofit | AT4: Updated Validated GrossMargin | AU4: Approved discount band | AV4: Won Deals | AW4: Column1
A5: D00003 | B5: 45646 | C5: C0001 | D5: LEG-0001 | E5: CT00001 | F5: Sales | G5: Legal | H5: South | I5: South Commercial | J5: SMB | K5: No | L5: 43891 | M5: 63 | N5: Nexus Enterprise Suite | O5: Renewal | Q5: 1 | R5: 54 | S5: M. Johnson | T5: 157663.13 | U5: =T5*DealsRawTable[[#This Row],[Contract_Years]] -> 157663.13 | V5: 0.066 | W5: 0.06 | X5: -0.119 | Y5: Renewal retention risk | Z5: Sales Manager | AA5: 148139.39 | AB5: =DealsRawTable[[#This Row],[Final_Price_ACV]]*DealsRawTable[[#This Row],[Contract_Years]] -> 148139.39 | AC5: 61223.551 | AD5: 86915.841 | AE5: 0.5867166 | AF5: Won | AG5: Yes | AI5: No | AJ5: 148139.39 | AK5: 86915.841 | AL5: Renewal of existing active contract | AM5: =ROUND(T5*(1-W5),2) -> 148203.34 | AN5: =DealsRawTable[[#This Row],[Validated_Annual_Final_Price]]*DealsRawTable[[#This Row],[Contract_Years]] -> 148203.34 | AO5: =DealsRawTable[[#This Row],[Validated_Annual_Final_Price]]-DealsRawTable[[#This Row],[Cost_to_Serve]] -> 86979.789 | AP5: =DealsRawTable[[#This Row],[Validated_Grossprofit]]/DealsRawTable[[#This Row],[Validated_Annual_Final_Price]] -> 0.58689493 | AQ5: 148203.34 | AR5: 148203.34 | AS5: 86979.789 | AT5: 0.58689493 | AU5: =IF(W5<=0.05,"0–5%", IF(W5<=0.1,"5–10%", IF(W5<=0.15,"10–15%", IF(W5<=0.2,"15–20%", IF(W5<=0.25,"20–25%", IF(W5<=0.3,"25–30%","Above 30%")))))) -> 5–10% | AV5: 116 | AW5: AVERAGEIFS($AT:$AT, $AU:$AU, AU5, $AV:$AV, "Won")
A6: D00004 | B6: 45863 | C6: C0001 | D6: LEG-0001 | E6: CT00001 | F6: Sales | G6: Legal | H6: South | I6: South Commercial | J6: SMB | K6: No | L6: 43891 | M6: 63 | N6: Nexus Enterprise Suite | O6: Expansion | P6: Module Add-on | Q6: 1 | R6: 66 | S6: M. Johnson | T6: 171556.91 | U6: =T6*DealsRawTable[[#This Row],[Contract_Years]] -> 171556.91 | V6: 0.012 | W6: 0.012 | X6: 0.079 | Y6: Expansion opportunity | Z6: Sales Manager | AA6: 169511.06 | AB6: =DealsRawTable[[#This Row],[Final_Price_ACV]]*DealsRawTable[[#This Row],[Contract_Years]] -> 169511.06 | AC6: 59147.753 | AD6: 110363.3 | AE6: 0.65106847 | AF6: Won | AH6: Yes | AI6: No | AJ6: 169511.06 | AK6: 110363.3 | AL6: Expansion allowed because contract was active | AM6: =ROUND(T6*(1-W6),2) -> 169498.23 | AN6: =DealsRawTable[[#This Row],[Validated_Annual_Final_Price]]*DealsRawTable[[#This Row],[Contract_Years]] -> 169498.23 | AO6: =DealsRawTable[[#This Row],[Validated_Annual_Final_Price]]-DealsRawTable[[#This Row],[Cost_to_Serve]] -> 110350.48 | AP6: =DealsRawTable[[#This Row],[Validated_Grossprofit]]/DealsRawTable[[#This Row],[Validated_Annual_Final_Price]] -> 0.65104206 | AQ6: 169498.23 | AR6: 169498.23 | AS6: 110350.48 | AT6: 0.65104206 | AU6: =IF(W6<=0.05,"0–5%", IF(W6<=0.1,"5–10%", IF(W6<=0.15,"10–15%", IF(W6<=0.2,"15–20%", IF(W6<=0.25,"20–25%", IF(W6<=0.3,"25–30%","Above 30%")))))) -> 0–5% | AV6: 55
A7: D00005 | B7: 46011 | C7: C0001 | D7: LEG-0001 | E7: CT00001 | F7: Sales | G7: Legal | H7: South | I7: South Commercial | J7: SMB | K7: No | L7: 43891 | M7: 63 | N7: Nexus Enterprise Suite | O7: Renewal | Q7: 1 | R7: 66 | S7: T. Brooks | T7: 183149.11 | U7: =T7*DealsRawTable[[#This Row],[Contract_Years]] -> 183149.11 | V7: 0.167 | W7: 0.148 | X7: -0.02 | Y7: Renewal retention risk | Z7: Pricing Analyst | AA7: 155982.63 | AB7: =DealsRawTable[[#This Row],[Final_Price_ACV]]*DealsRawTable[[#This Row],[Contract_Years]] -> 155982.63 | AC7: 64410.549 | AD7: 91572.082 | AE7: 0.58706589 | AF7: Won | AG7: Yes | AI7: No | AJ7: 155982.63 | AK7: 91572.082 | AL7: Renewal of existing active contract | AM7: =ROUND(T7*(1-W7),2) -> 156043.04 | AN7: =DealsRawTable[[#This Row],[Validated_Annual_Final_Price]]*DealsRawTable[[#This Row],[Contract_Years]] -> 156043.04 | AO7: =DealsRawTable[[#This Row],[Validated_Annual_Final_Price]]-DealsRawTable[[#This Row],[Cost_to_Serve]] -> 91632.491 | AP7: =DealsRawTable[[#This Row],[Validated_Grossprofit]]/DealsRawTable[[#This Row],[Validated_Annual_Final_Price]] -> 0.58722575 | AQ7: 156043.04 | AR7: 156043.04 | AS7: 91632.491 | AT7: 0.58722575 | AU7: =IF(W7<=0.05,"0–5%", IF(W7<=0.1,"5–10%", IF(W7<=0.15,"10–15%", IF(W7<=0.2,"15–20%", IF(W7<=0.25,"20–25%", IF(W7<=0.3,"25–30%","Above 30%")))))) -> 10–15% | AV7: 113
A8: D00006 | B8: 45578 | C8: C0002 | D8: LEG-0002 | E8: CT00002 | F8: Finance | G8: Legal | H8: South | I8: South Enterprise | J8: Enterprise | K8: Yes | L8: 44958 | M8: 74 | N8: Nexus Enterprise Suite | O8: New Business | Q8: 1 | R8: 1133 | S8: R. Singh | T8: 448091.47 | U8: =T8*DealsRawTable[[#This Row],[Contract_Years]] -> 448091.47 | V8: 0.211 | W8: 0.2 | X8: 0.104 | Y8: Renewal retention risk | Z8: Business Manager | AA8: 358284.32 | AB8: =DealsRawTable[[#This Row],[Final_Price_ACV]]*DealsRawTable[[#This Row],[Contract_Years]] -> 358284.32 | AC8: 180745.64 | AD8: 177538.68 | AE8: 0.49552456 | AF8: Won | AI8: No | AJ8: 358284.32 | AK8: 177538.68 | AL8: First purchase under this contract | AM8: =ROUND(T8*(1-W8),2) -> 358473.18 | AN8: =DealsRawTable[[#This Row],[Validated_Annual_Final_Price]]*DealsRawTable[[#This Row],[Contract_Years]] -> 358473.18 | AO8: =DealsRawTable[[#This Row],[Validated_Annual_Final_Price]]-DealsRawTable[[#This Row],[Cost_to_Serve]] -> 177727.54 | AP8: =DealsRawTable[[#This Row],[Validated_Grossprofit]]/DealsRawTable[[#This Row],[Validated_Annual_Final_Price]] -> 0.49579034 | AQ8: 358473.18 | AR8: 358473.18 | AS8: 177727.54 | AT8: 0.49579034 | AU8: =IF(W8<=0.05,"0–5%", IF(W8<=0.1,"5–10%", IF(W8<=0.15,"10–15%", IF(W8<=0.2,"15–20%", IF(W8<=0.25,"20–25%", IF(W8<=0.3,"25–30%","Above 30%")))))) -> 15–20% | AV8: 108
A9: D00007 | B9: 45943 | C9: C0002 | D9: LEG-0002 | E9: CT00002 | F9: Finance | G9: Legal | H9: South | I9: South Enterprise | J9: Enterprise | K9: Yes | L9: 44958 | M9: 74 | N9: Nexus Enterprise Suite | O9: Renewal | Q9: 1 | R9: 1133 | S9: L. Williams | T9: 470220.96 | U9: =T9*DealsRawTable[[#This Row],[Contract_Years]] -> 470220.96 | V9: 0.147 | W9: 0.089 | X9: -0.086 | Y9: Multi-year commitment | Z9: Sales Manager | AA9: 428472.21 | AB9: =DealsRawTable[[#This Row],[Final_Price_ACV]]*DealsRawTable[[#This Row],[Contract_Years]] -> 428472.21 | AC9: 163165.18 | AD9: 265307.03 | AE9: 0.61919309 | AF9: Won | AG9: Yes | AI9: No | AJ9: 428472.21 | AK9: 265307.03 | AL9: Renewal of existing active contract | AM9: =ROUND(T9*(1-W9),2) -> 428371.3 | AN9: =DealsRawTable[[#This Row],[Validated_Annual_Final_Price]]*DealsRawTable[[#This Row],[Contract_Years]] -> 428371.3 | AO9: =DealsRawTable[[#This Row],[Validated_Annual_Final_Price]]-DealsRawTable[[#This Row],[Cost_to_Serve]] -> 265206.12 | AP9: =DealsRawTable[[#This Row],[Validated_Grossprofit]]/DealsRawTable[[#This Row],[Validated_Annual_Final_Price]] -> 0.61910338 | AQ9: 428371.3 | AR9: 428371.3 | AS9: 265206.12 | AT9: 0.61910338 | AU9: =IF(W9<=0.05,"0–5%", IF(W9<=0.1,"5–10%", IF(W9<=0.15,"10–15%", IF(W9<=0.2,"15–20%", IF(W9<=0.25,"20–25%", IF(W9<=0.3,"25–30%","Above 30%")))))) -> 5–10% | AV9: 116
A10: D00008 | B10: 45872 | C10: C0003 | D10: TEC-0003 | E10: CT00004 | F10: Legal | G10: Technology | H10: Northeast | I10: Northeast Commercial | J10: SMB | K10: No | L10: 44256 | M10: 87 | N10: Nexus Insights | O10: Expansion | P10: Storage / Usage Expansion | Q10: 3 | R10: 30 | S10: A. Patel | T10: 30632.964 | U10: =T10*DealsRawTable[[#This Row],[Contract_Years]] -> 91898.893 | V10: 0.148 | W10: 0.137 | X10: 0.054 | Y10: Expansion opportunity | Z10: Pricing Analyst | AA10: 26446.113 | AB10: =DealsRawTable[[#This Row],[Final_Price_ACV]]*DealsRawTable[[#This Row],[Contract_Years]] -> 79338.34 | AC10: 8043.5155 | AD10: 18402.598 | AE10: 0.69585264 | AF10: Won | AH10: Yes | AI10: No | AJ10: 26446.113 | AK10: 18402.598 | AL10: Expansion allowed because contract was active | AM10: =ROUND(T10*(1-W10),2) -> 26436.25 | AN10: =DealsRawTable[[#This Row],[Validated_Annual_Final_Price]]*DealsRawTable[[#This Row],[Contract_Years]] -> 79308.75 | AO10: =DealsRawTable[[#This Row],[Validated_Annual_Final_Price]]-DealsRawTable[[#This Row],[Cost_to_Serve]] -> 18392.734 | AP10: =DealsRawTable[[#This Row],[Validated_Grossprofit]]/DealsRawTable[[#This Row],[Validated_Annual_Final_Price]] -> 0.69573916 | AQ10: 26436.25 | AR10: 79308.75 | AS10: 18392.734 | AT10: 0.69573916 | AU10: =IF(W10<=0.05,"0–5%", IF(W10<=0.1,"5–10%", IF(W10<=0.15,"10–15%", IF(W10<=0.2,"15–20%", IF(W10<=0.25,"20–25%", IF(W10<=0.3,"25–30%","Above 30%")))))) -> 10–15% | AV10: 113
A11: D00009 | B11: 46012 | C11: C0003 | D11: TEC-0003 | E11: CT00004 | F11: Legal | G11: Technology | H11: Northeast | I11: Northeast Commercial | J11: SMB | K11: No | L11: 44256 | M11: 87 | N11: Nexus Insights | O11: Renewal | Q11: 3 | R11: 30 | S11: M. Johnson | T11: 33055.576 | U11: =T11*DealsRawTable[[#This Row],[Contract_Years]] -> 99166.728 | V11: 0.154 | W11: 0.12 | X11: -0.081 | Y11: Verified competitor pressure | Z11: Pricing Analyst | AA11: 29083.19 | AB11: =DealsRawTable[[#This Row],[Final_Price_ACV]]*DealsRawTable[[#This Row],[Contract_Years]] -> 87249.57 | AC11: 8527.9708 | AD11: 20555.219 | AE11: 0.7067732 | AF11: Won | AG11: Yes | AI11: No | AJ11: 29083.19 | AK11: 20555.219 | AL11: Renewal of existing active contract | AM11: =ROUND(T11*(1-W11),2) -> 29088.91 | AN11: =DealsRawTable[[#This Row],[Validated_Annual_Final_Price]]*DealsRawTable[[#This Row],[Contract_Years]] -> 87266.73 | AO11: =DealsRawTable[[#This Row],[Validated_Annual_Final_Price]]-DealsRawTable[[#This Row],[Cost_to_Serve]] -> 20560.939 | AP11: =DealsRawTable[[#This Row],[Validated_Grossprofit]]/DealsRawTable[[#This Row],[Validated_Annual_Final_Price]] -> 0.70683086 | AQ11: 29088.91 | AR11: 87266.73 | AS11: 20560.939 | AT11: 0.70683086 | AU11: =IF(W11<=0.05,"0–5%", IF(W11<=0.1,"5–10%", IF(W11<=0.15,"10–15%", IF(W11<=0.2,"15–20%", IF(W11<=0.25,"20–25%", IF(W11<=0.3,"25–30%","Above 30%")))))) -> 10–15% | AV11: 113
A12: D00010 | B12: 45567 | C12: C0004 | D12: FIN-0004 | E12: CT00005 | F12: Finance | G12: Financial Services | H12: West | I12: West Commercial | J12: Mid-Market | K12: No | L12: 45383 | M12: 50 | N12: Nexus AI Assistant | O12: New Business | Q12: 3 | R12: 176 | S12: R. Singh | T12: 64148.04 | U12: =T12*DealsRawTable[[#This Row],[Contract_Years]] -> 192444.12 | V12: 0.189 | W12: 0.188 | X12: -0.013 | Y12: Verified competitor pressure | Z12: Pricing Analyst | AA12: 52095.758 | AB12: =DealsRawTable[[#This Row],[Final_Price_ACV]]*DealsRawTable[[#This Row],[Contract_Years]] -> 156287.27 | AC12: 27124.236 | AD12: 24971.522 | AE12: 0.47933887 | AF12: Won | AI12: No | AJ12: 52095.758 | AK12: 24971.522 | AL12: First purchase under this contract | AM12: =ROUND(T12*(1-W12),2) -> 52088.21 | AN12: =DealsRawTable[[#This Row],[Validated_Annual_Final_Price]]*DealsRawTable[[#This Row],[Contract_Years]] -> 156264.63 | AO12: =DealsRawTable[[#This Row],[Validated_Annual_Final_Price]]-DealsRawTable[[#This Row],[Cost_to_Serve]] -> 24963.974 | AP12: =DealsRawTable[[#This Row],[Validated_Grossprofit]]/DealsRawTable[[#This Row],[Validated_Annual_Final_Price]] -> 0.47926342 | AQ12: 52088.21 | AR12: 156264.63 | AS12: 24963.974 | AT12: 0.47926342 | AU12: =IF(W12<=0.05,"0–5%", IF(W12<=0.1,"5–10%", IF(W12<=0.15,"10–15%", IF(W12<=0.2,"15–20%", IF(W12<=0.25,"20–25%", IF(W12<=0.3,"25–30%","Above 30%")))))) -> 15–20% | AV12: 108
A13: D00011 | B13: 45821 | C13: C0004 | D13: FIN-0004 | E13: CT00006 | F13: Legal | G13: Financial Services | H13: West | I13: West Commercial | J13: Mid-Market | K13: No | L13: 45383 | M13: 50 | N13: Nexus Enterprise Suite | O13: New Business | Q13: 1 | R13: 141 | S13: L. Williams | T13: 223858.23 | U13: =T13*DealsRawTable[[#This Row],[Contract_Years]] -> 223858.23 | V13: 0.167 | W13: 0.119 | X13: -0.049 | Y13: Strategic logo opportunity | Z13: Pricing Analyst | AA13: 197151.93 | AB13: =DealsRawTable[[#This Row],[Final_Price_ACV]]*DealsRawTable[[#This Row],[Contract_Years]] -> 197151.93 | AC13: 94186.983 | AD13: 102964.94 | AE13: 0.52226192 | AF13: Won | AI13: No | AJ13: 197151.93 | AK13: 102964.94 | AL13: First purchase under this contract | AM13: =ROUND(T13*(1-W13),2) -> 197219.1 | AN13: =DealsRawTable[[#This Row],[Validated_Annual_Final_Price]]*DealsRawTable[[#This Row],[Contract_Years]] -> 197219.1 | AO13: =DealsRawTable[[#This Row],[Validated_Annual_Final_Price]]-DealsRawTable[[#This Row],[Cost_to_Serve]] -> 103032.12 | AP13: =DealsRawTable[[#This Row],[Validated_Grossprofit]]/DealsRawTable[[#This Row],[Validated_Annual_Final_Price]] -> 0.52242464 | AQ13: 197219.1 | AR13: 197219.1 | AS13: 103032.12 | AT13: 0.52242464 | AU13: =IF(W13<=0.05,"0–5%", IF(W13<=0.1,"5–10%", IF(W13<=0.15,"10–15%", IF(W13<=0.2,"15–20%", IF(W13<=0.25,"20–25%", IF(W13<=0.3,"25–30%","Above 30%")))))) -> 10–15% | AV13: 113
A14: D00012 | B14: 45663 | C14: C0005 | D14: HEA-0005 | E14: CT00007 | F14: Technology | G14: Healthcare | H14: South | I14: South Commercial | J14: Mid-Market | K14: No | L14: 43952 | M14: 66 | N14: Nexus Enterprise Suite | O14: Renewal | Q14: 3 | R14: 276 | S14: D. Chen | T14: 340477.39 | U14: =T14*DealsRawTable[[#This Row],[Contract_Years]] -> 1021432.2 | V14: 0.159 | W14: 0.13 | X14: -0.081 | Y14: Verified competitor pressure | Z14: Pricing Analyst | AA14: 296123.33 | AB14: =DealsRawTable[[#This Row],[Final_Price_ACV]]*DealsRawTable[[#This Row],[Contract_Years]] -> 888369.98 | AC14: 134110.72 | AD14: 162012.61 | AE14: 0.54711193 | AF14: Lost | AG14: No | AI14: No | AJ14: 0 | AK14: 0 | AL14: Renewal of existing active contract | AM14: =ROUND(T14*(1-W14),2) -> 296215.33 | AN14: =DealsRawTable[[#This Row],[Validated_Annual_Final_Price]]*DealsRawTable[[#This Row],[Contract_Years]] -> 888645.99 | AO14: =DealsRawTable[[#This Row],[Validated_Annual_Final_Price]]-DealsRawTable[[#This Row],[Cost_to_Serve]] -> 162104.61 | AP14: =DealsRawTable[[#This Row],[Validated_Grossprofit]]/DealsRawTable[[#This Row],[Validated_Annual_Final_Price]] -> 0.5472526 | AQ14: 0 | AR14: 0 | AS14: 0 | AT14: 0 | AU14: =IF(W14<=0.05,"0–5%", IF(W14<=0.1,"5–10%", IF(W14<=0.15,"10–15%", IF(W14<=0.2,"15–20%", IF(W14<=0.25,"20–25%", IF(W14<=0.3,"25–30%","Above 30%")))))) -> 10–15% | AV14: 113
A15: D00013 | B15: 45804 | C15: C0005 | D15: HEA-0005 | E15: CT00008 | F15: Legal | G15: Healthcare | H15: South | I15: South Commercial | J15: Mid-Market | K15: No | L15: 43952 | M15: 66 | N15: Nexus Enterprise Suite | O15: New Business | Q15: 1 | R15: 110 | S15: R. Singh | T15: 320597.41 | U15: =T15*DealsRawTable[[#This Row],[Contract_Years]] -> 320597.41 | V15: 0.191 | W15: 0.188 | X15: -0.007 | Y15: Procurement requirement | Z15: Pricing Analyst | AA15: 260342.6 | AB15: =DealsRawTable[[#This Row],[Final_Price_ACV]]*DealsRawTable[[#This Row],[Contract_Years]] -> 260342.6 | AC15: 126422.67 | AD15: 133919.93 | AE15: 0.51439882 | AF15: Lost | AI15: No | AJ15: 0 | AK15: 0 | AL15: First purchase under this contract | AM15: =ROUND(T15*(1-W15),2) -> 260325.1 | AN15: =DealsRawTable[[#This Row],[Validated_Annual_Final_Price]]*DealsRawTable[[#This Row],[Contract_Years]] -> 260325.1 | AO15: =DealsRawTable[[#This Row],[Validated_Annual_Final_Price]]-DealsRawTable[[#This Row],[Cost_to_Serve]] -> 133902.43 | AP15: =DealsRawTable[[#This Row],[Validated_Grossprofit]]/DealsRawTable[[#This Row],[Validated_Annual_Final_Price]] -> 0.51436618 | AQ15: 0 | AR15: 0 | AS15: 0 | AT15: 0 | AU15: =IF(W15<=0.05,"0–5%", IF(W15<=0.1,"5–10%", IF(W15<=0.15,"10–15%", IF(W15<=0.2,"15–20%", IF(W15<=0.25,"20–25%", IF(W15<=0.3,"25–30%","Above 30%")))))) -> 15–20% | AV15: 108
A16: D00014 | B16: 45340 | C16: C0005 | D16: HEA-0005 | E16: CT00009 | F16: Finance | G16: Healthcare | H16: South | I16: South Commercial | J16: Mid-Market | K16: No | L16: 43952 | M16: 66 | N16: Nexus AI Assistant | O16: Renewal | Q16: 1 | R16: 99 | S16: A. Patel | T16: 110842.81 | U16: =T16*DealsRawTable[[#This Row],[Contract_Years]] -> 110842.81 | V16: 0.185 | W16: 0.168 | X16: -0.131 | Y16: Budget constraint | Z16: Pricing Analyst | AA16: 92186.507 | AB16: =DealsRawTable[[#This Row],[Final_Price_ACV]]*DealsRawTable[[#This Row],[Contract_Years]] -> 92186.507 | AC16: 40259.459 | AD16: 51927.049 | AE16: 0.56328253 | AF16: Lost | AG16: No | AI16: No | AJ16: 0 | AK16: 0 | AL16: Renewal of existing active contract | AM16: =ROUND(T16*(1-W16),2) -> 92221.22 | AN16: =DealsRawTable[[#This Row],[Validated_Annual_Final_Price]]*DealsRawTable[[#This Row],[Contract_Years]] -> 92221.22 | AO16: =DealsRawTable[[#This Row],[Validated_Annual_Final_Price]]-DealsRawTable[[#This Row],[Cost_to_Serve]] -> 51961.761 | AP16: =DealsRawTable[[#This Row],[Validated_Grossprofit]]/DealsRawTable[[#This Row],[Validated_Annual_Final_Price]] -> 0.56344691 | AQ16: 0 | AR16: 0 | AS16: 0 | AT16: 0 | AU16: =IF(W16<=0.05,"0–5%", IF(W16<=0.1,"5–10%", IF(W16<=0.15,"10–15%", IF(W16<=0.2,"15–20%", IF(W16<=0.25,"20–25%", IF(W16<=0.3,"25–30%","Above 30%")))))) -> 15–20% | AV16: 108
A17: D00017 | B17: 45432 | C17: C0005 | D17: HEA-0005 | E17: CT00010 | F17: Legal | G17: Healthcare | H17: South | I17: South Commercial | J17: Mid-Market | K17: No | L17: 43952 | M17: 66 | N17: Nexus Compliance | O17: Renewal | Q17: 1 | R17: 209 | S17: T. Brooks | T17: 110315.32 | U17: =T17*DealsRawTable[[#This Row],[Contract_Years]] -> 110315.32 | V17: 0.137 | W17: 0.115 | X17: -0.041 | Y17: Expansion opportunity | Z17: Pricing Analyst | AA17: 97591.585 | AB17: =DealsRawTable[[#This Row],[Final_Price_ACV]]*DealsRawTable[[#This Row],[Contract_Years]] -> 97591.585 | AC17: 37804.254 | AD17: 59787.331 | AE17: 0.61262793 | AF17: Won | AG17: Yes | AI17: No | AJ17: 97591.585 | AK17: 59787.331 | AL17: Renewal of existing active contract | AM17: =ROUND(T17*(1-W17),2) -> 97629.05 | AN17: =DealsRawTable[[#This Row],[Validated_Annual_Final_Price]]*DealsRawTable[[#This Row],[Contract_Years]] -> 97629.05 | AO17: =DealsRawTable[[#This Row],[Validated_Annual_Final_Price]]-DealsRawTable[[#This Row],[Cost_to_Serve]] -> 59824.796 | AP17: =DealsRawTable[[#This Row],[Validated_Grossprofit]]/DealsRawTable[[#This Row],[Validated_Annual_Final_Price]] -> 0.61277659 | AQ17: 97629.05 | AR17: 97629.05 | AS17: 59824.796 | AT17: 0.61277659 | AU17: =IF(W17<=0.05,"0–5%", IF(W17<=0.1,"5–10%", IF(W17<=0.15,"10–15%", IF(W17<=0.2,"15–20%", IF(W17<=0.25,"20–25%", IF(W17<=0.3,"25–30%","Above 30%")))))) -> 10–15% | AV17: 113
A18: D00018 | B18: 45797 | C18: C0005 | D18: HEA-0005 | E18: CT00010 | F18: Legal | G18: Healthcare | H18: South | I18: South Commercial | J18: Mid-Market | K18: No | L18: 43952 | M18: 66 | N18: Nexus Compliance | O18: Renewal | Q18: 1 | R18: 209 | S18: M. Johnson | T18: 117035.83 | U18: =T18*DealsRawTable[[#This Row],[Contract_Years]] -> 117035.83 | V18: 0.213 | W18: 0.212 | X18: -0.001 | Y18: Budget constraint | Z18: Business Manager | AA18: 92239.591 | AB18: =DealsRawTable[[#This Row],[Final_Price_ACV]]*DealsRawTable[[#This Row],[Contract_Years]] -> 92239.591 | AC18: 45049.823 | AD18: 47189.768 | AE18: 0.51159992 | AF18: Lost | AG18: No | AI18: No | AJ18: 0 | AK18: 0 | AL18: Renewal of existing active contract | AM18: =ROUND(T18*(1-W18),2) -> 92224.24 | AN18: =DealsRawTable[[#This Row],[Validated_Annual_Final_Price]]*DealsRawTable[[#This Row],[Contract_Years]] -> 92224.24 | AO18: =DealsRawTable[[#This Row],[Validated_Annual_Final_Price]]-DealsRawTable[[#This Row],[Cost_to_Serve]] -> 47174.417 | AP18: =DealsRawTable[[#This Row],[Validated_Grossprofit]]/DealsRawTable[[#This Row],[Validated_Annual_Final_Price]] -> 0.51151863 | AQ18: 0 | AR18: 0 | AS18: 0 | AT18: 0 | AU18: =IF(W18<=0.05,"0–5%", IF(W18<=0.1,"5–10%", IF(W18<=0.15,"10–15%", IF(W18<=0.2,"15–20%", IF(W18<=0.25,"20–25%", IF(W18<=0.3,"25–30%","Above 30%")))))) -> 20–25% | AV18: 29
A19: D00019 | B19: 45925 | C19: C0005 | D19: HEA-0005 | E19: CT00010 | F19: Legal | G19: Healthcare | H19: South | I19: South Commercial | J19: Mid-Market | K19: No | L19: 43952 | M19: 66 | N19: Nexus Compliance | O19: Win-back | Q19: 1 | R19: 209 | S19: D. Chen | T19: 117035.83 | U19: =T19*DealsRawTable[[#This Row],[Contract_Years]] -> 117035.83 | V19: 0.274 | W19: 0.264 | X19: -0.041 | Y19: Renewal retention risk | Z19: Business Manager | AA19: 86133.571 | AB19: =DealsRawTable[[#This Row],[Final_Price_ACV]]*DealsRawTable[[#This Row],[Contract_Years]] -> 86133.571 | AC19: 38249.246 | AD19: 47884.325 | AE19: 0.55593103 | AF19: Won | AI19: Yes | AJ19: 86133.571 | AK19: 47884.325 | AL19: Customer returned after lost renewal | AM19: =ROUND(T19*(1-W19),2) -> 86138.37 | AN19: =DealsRawTable[[#This Row],[Validated_Annual_Final_Price]]*DealsRawTable[[#This Row],[Contract_Years]] -> 86138.37 | AO19: =DealsRawTable[[#This Row],[Validated_Annual_Final_Price]]-DealsRawTable[[#This Row],[Cost_to_Serve]] -> 47889.124 | AP19: =DealsRawTable[[#This Row],[Validated_Grossprofit]]/DealsRawTable[[#This Row],[Validated_Annual_Final_Price]] -> 0.55595577 | AQ19: 86138.37 | AR19: 86138.37 | AS19: 47889.124 | AT19: 0.55595577 | AU19: =IF(W19<=0.05,"0–5%", IF(W19<=0.1,"5–10%", IF(W19<=0.15,"10–15%", IF(W19<=0.2,"15–20%", IF(W19<=0.25,"20–25%", IF(W19<=0.3,"25–30%","Above 30%")))))) -> 25–30% | AV19: 3
A20: D00020 | B20: 45344 | C20: C0006 | D20: LEG-0006 | E20: CT00011 | F20: Legal | G20: Legal | H20: West | I20: West Commercial | J20: Mid-Market | K20: No | L20: 45323 | M20: 73 | N20: Nexus Compliance | O20: New Business | Q20: 1 | R20: 131 | S20: R. Singh | T20: 184726.34 | U20: =T20*DealsRawTable[[#This Row],[Contract_Years]] -> 184726.34 | V20: 0.127 | W20: 0.099 | X20: 0.036 | Y20: Expansion opportunity | Z20: Sales Manager | AA20: 166516.73 | AB20: =DealsRawTable[[#This Row],[Final_Price_ACV]]*DealsRawTable[[#This Row],[Contract_Years]] -> 166516.73 | AC20: 58415.092 | AD20: 108101.64 | AE20: 0.64919386 | AF20: Lost | AI20: No | AJ20: 0 | AK20: 0 | AL20: First purchase under this contract | AM20: =ROUND(T20*(1-W20),2) -> 166438.43 | AN20: =DealsRawTable[[#This Row],[Validated_Annual_Final_Price]]*DealsRawTable[[#This Row],[Contract_Years]] -> 166438.43 | AO20: =DealsRawTable[[#This Row],[Validated_Annual_Final_Price]]-DealsRawTable[[#This Row],[Cost_to_Serve]] -> 108023.34 | AP20: =DealsRawTable[[#This Row],[Validated_Grossprofit]]/DealsRawTable[[#This Row],[Validated_Annual_Final_Price]] -> 0.64902882 | AQ20: 0 | AR20: 0 | AS20: 0 | AT20: 0 | AU20: =IF(W20<=0.05,"0–5%", IF(W20<=0.1,"5–10%", IF(W20<=0.15,"10–15%", IF(W20<=0.2,"15–20%", IF(W20<=0.25,"20–25%", IF(W20<=0.3,"25–30%","Above 30%")))))) -> 5–10% | AV20: 116
A21: D00021 | B21: 45685 | C21: C0006 | D21: LEG-0006 | E21: CT00012 | F21: Finance | G21: Legal | H21: West | I21: West Commercial | J21: Mid-Market | K21: No | L21: 45323 | M21: 73 | N21: Nexus Enterprise Suite | O21: New Business | Q21: 1 | R21: 210 | S21: M. Johnson | T21: 259121.64 | U21: =T21*DealsRawTable[[#This Row],[Contract_Years]] -> 259121.64 | V21: 0.138 | W21: 0.103 | X21: 0.112 | Y21: Expansion opportunity | Z21: Pricing Analyst | AA21: 232470.33 | AB21: =DealsRawTable[[#This Row],[Final_Price_ACV]]*DealsRawTable[[#This Row],[Contract_Years]] -> 232470.33 | AC21: 92801.566 | AD21: 139668.77 | AE21: 0.60080254 | AF21: Lost | AI21: No | AJ21: 0 | AK21: 0 | AL21: First purchase under this contract | AM21: =ROUND(T21*(1-W21),2) -> 232432.11 | AN21: =DealsRawTable[[#This Row],[Validated_Annual_Final_Price]]*DealsRawTable[[#This Row],[Contract_Years]] -> 232432.11 | AO21: =DealsRawTable[[#This Row],[Validated_Annual_Final_Price]]-DealsRawTable[[#This Row],[Cost_to_Serve]] -> 139630.54 | AP21: =DealsRawTable[[#This Row],[Validated_Grossprofit]]/DealsRawTable[[#This Row],[Validated_Annual_Final_Price]] -> 0.6007369 | AQ21: 0 | AR21: 0 | AS21: 0 | AT21: 0 | AU21: =IF(W21<=0.05,"0–5%", IF(W21<=0.1,"5–10%", IF(W21<=0.15,"10–15%", IF(W21<=0.2,"15–20%", IF(W21<=0.25,"20–25%", IF(W21<=0.3,"25–30%","Above 30%")))))) -> 10–15% | AV21: 113
A22: D00022 | B22: 45341 | C22: C0006 | D22: LEG-0006 | E22: CT00013 | F22: Sales | G22: Legal | H22: West | I22: West Commercial | J22: Mid-Market | K22: No | L22: 45323 | M22: 73 | N22: Nexus Enterprise Suite | O22: New Business | Q22: 3 | R22: 213 | S22: T. Brooks | T22: 196873.51 | U22: =T22*DealsRawTable[[#This Row],[Contract_Years]] -> 590620.52 | V22: 0.069 | W22: 0.033 | X22: 0.15 | Y22: Verified competitor pressure | Z22: Sales Manager | AA22: 190467.75 | AB22: =DealsRawTable[[#This Row],[Final_Price_ACV]]*DealsRawTable[[#This Row],[Contract_Years]] -> 571403.24 | AC22: 70817.896 | AD22: 119649.85 | AE22: 0.62818956 | AF22: Won | AI22: No | AJ22: 190467.75 | AK22: 119649.85 | AL22: First purchase under this contract | AM22: =ROUND(T22*(1-W22),2) -> 190376.68 | AN22: =DealsRawTable[[#This Row],[Validated_Annual_Final_Price]]*DealsRawTable[[#This Row],[Contract_Years]] -> 571130.04 | AO22: =DealsRawTable[[#This Row],[Validated_Annual_Final_Price]]-DealsRawTable[[#This Row],[Cost_to_Serve]] -> 119558.78 | AP22: =DealsRawTable[[#This Row],[Validated_Grossprofit]]/DealsRawTable[[#This Row],[Validated_Annual_Final_Price]] -> 0.62801171 | AQ22: 190376.68 | AR22: 571130.04 | AS22: 119558.78 | AT22: 0.62801171 | AU22: =IF(W22<=0.05,"0–5%", IF(W22<=0.1,"5–10%", IF(W22<=0.15,"10–15%", IF(W22<=0.2,"15–20%", IF(W22<=0.25,"20–25%", IF(W22<=0.3,"25–30%","Above 30%")))))) -> 0–5% | AV22: 55
A23: D00023 | B23: 45310 | C23: C0007 | D23: FIN-0007 | E23: CT00014 | F23: Finance | G23: Financial Services | H23: Northeast | I23: Northeast Commercial | J23: Mid-Market | K23: No | L23: 43160 | M23: 47 | N23: Nexus Analytics | O23: New Business | Q23: 2 | R23: 204 | S23: D. Chen | T23: 112696.57 | U23: =T23*DealsRawTable[[#This Row],[Contract_Years]] -> 225393.13 | V23: 0.218 | W23: 0.195 | X23: -0.072 | Y23: Verified competitor pressure | Z23: Pricing Analyst | AA23: 90720.722 | AB23: =DealsRawTable[[#This Row],[Final_Price_ACV]]*DealsRawTable[[#This Row],[Contract_Years]] -> 181441.44 | AC23: 40187.432 | AD23: 50533.29 | AE23: 0.55702037 | AF23: Lost | AI23: No | AJ23: 0 | AK23: 0 | AL23: First purchase under this contract | AM23: =ROUND(T23*(1-W23),2) -> 90720.74 | AN23: =DealsRawTable[[#This Row],[Validated_Annual_Final_Price]]*DealsRawTable[[#This Row],[Contract_Years]] -> 181441.48 | AO23: =DealsRawTable[[#This Row],[Validated_Annual_Final_Price]]-DealsRawTable[[#This Row],[Cost_to_Serve]] -> 50533.308 | AP23: =DealsRawTable[[#This Row],[Validated_Grossprofit]]/DealsRawTable[[#This Row],[Validated_Annual_Final_Price]] -> 0.55702045 | AQ23: 0 | AR23: 0 | AS23: 0 | AT23: 0 | AU23: =IF(W23<=0.05,"0–5%", IF(W23<=0.1,"5–10%", IF(W23<=0.15,"10–15%", IF(W23<=0.2,"15–20%", IF(W23<=0.25,"20–25%", IF(W23<=0.3,"25–30%","Above 30%")))))) -> 15–20% | AV23: 108
A24: D00026 | B24: 45504 | C24: C0007 | D24: FIN-0007 | E24: CT00015 | F24: Finance | G24: Financial Services | H24: Northeast | I24: Northeast Commercial | J24: Mid-Market | K24: No | L24: 43160 | M24: 47 | N24: Nexus Insights | O24: Renewal | Q24: 1 | R24: 305 | S24: T. Brooks | T24: 65414.55 | U24: =T24*DealsRawTable[[#This Row],[Contract_Years]] -> 65414.55 | V24: 0.163 | W24: 0.149 | X24: -0.023 | Y24: Renewal retention risk | Z24: Pricing Analyst | AA24: 55639.64 | AB24: =DealsRawTable[[#This Row],[Final_Price_ACV]]*DealsRawTable[[#This Row],[Contract_Years]] -> 55639.64 | AC24: 19905.247 | AD24: 35734.393 | AE24: 0.64224702 | AF24: Lost | AG24: No | AI24: No | AJ24: 0 | AK24: 0 | AL24: Renewal of existing active contract | AM24: =ROUND(T24*(1-W24),2) -> 55667.78 | AN24: =DealsRawTable[[#This Row],[Validated_Annual_Final_Price]]*DealsRawTable[[#This Row],[Contract_Years]] -> 55667.78 | AO24: =DealsRawTable[[#This Row],[Validated_Annual_Final_Price]]-DealsRawTable[[#This Row],[Cost_to_Serve]] -> 35762.533 | AP24: =DealsRawTable[[#This Row],[Validated_Grossprofit]]/DealsRawTable[[#This Row],[Validated_Annual_Final_Price]] -> 0.64242786 | AQ24: 0 | AR24: 0 | AS24: 0 | AT24: 0 | AU24: =IF(W24<=0.05,"0–5%", IF(W24<=0.1,"5–10%", IF(W24<=0.15,"10–15%", IF(W24<=0.2,"15–20%", IF(W24<=0.25,"20–25%", IF(W24<=0.3,"25–30%","Above 30%")))))) -> 10–15% | AV24: 113
A25: D00027 | B25: 45391 | C25: C0007 | D25: FIN-0007 | E25: CT00016 | F25: Corporate | G25: Financial Services | H25: Northeast | I25: Northeast Commercial | J25: Mid-Market | K25: No | L25: 43160 | M25: 47 | N25: Nexus Compliance | O25: Renewal | Q25: 1 | R25: 227 | S25: M. Johnson | T25: 92718.099 | U25: =T25*DealsRawTable[[#This Row],[Contract_Years]] -> 92718.099 | V25: 0.197 | W25: 0.195 | X25: -0.114 | Y25: Renewal retention risk | Z25: Pricing Analyst | AA25: 74619.853 | AB25: =DealsRawTable[[#This Row],[Final_Price_ACV]]*DealsRawTable[[#This Row],[Contract_Years]] -> 74619.853 | AC25: 35433.595 | AD25: 39186.259 | AE25: 0.52514521 | AF25: Won | AG25: Yes | AI25: No | AJ25: 74619.853 | AK25: 39186.259 | AL25: Renewal of existing active contract | AM25: =ROUND(T25*(1-W25),2) -> 74638.07 | AN25: =DealsRawTable[[#This Row],[Validated_Annual_Final_Price]]*DealsRawTable[[#This Row],[Contract_Years]] -> 74638.07 | AO25: =DealsRawTable[[#This Row],[Validated_Annual_Final_Price]]-DealsRawTable[[#This Row],[Cost_to_Serve]] -> 39204.475 | AP25: =DealsRawTable[[#This Row],[Validated_Grossprofit]]/DealsRawTable[[#This Row],[Validated_Annual_Final_Price]] -> 0.5252611 | AQ25: 74638.07 | AR25: 74638.07 | AS25: 39204.475 | AT25: 0.5252611 | AU25: =IF(W25<=0.05,"0–5%", IF(W25<=0.1,"5–10%", IF(W25<=0.15,"10–15%", IF(W25<=0.2,"15–20%", IF(W25<=0.25,"20–25%", IF(W25<=0.3,"25–30%","Above 30%")))))) -> 15–20% | AV25: 108
A26: D00028 | B26: 45756 | C26: C0007 | D26: FIN-0007 | E26: CT00016 | F26: Corporate | G26: Financial Services | H26: Northeast | I26: Northeast Commercial | J26: Mid-Market | K26: No | L26: 43160 | M26: 47 | N26: Nexus Compliance | O26: Renewal | Q26: 1 | R26: 227 | S26: T. Brooks | T26: 99705.748 | U26: =T26*DealsRawTable[[#This Row],[Contract_Years]] -> 99705.748 | V26: 0.209 | W26: 0.177 | X26: 0.012 | Y26: Renewal retention risk | Z26: Pricing Analyst | AA26: 82087.561 | AB26: =DealsRawTable[[#This Row],[Final_Price_ACV]]*DealsRawTable[[#This Row],[Contract_Years]] -> 82087.561 | AC26: 37524.631 | AD26: 44562.93 | AE26: 0.54287068 | AF26: Won | AG26: Yes | AI26: No | AJ26: 82087.561 | AK26: 44562.93 | AL26: Renewal of existing active contract | AM26: =ROUND(T26*(1-W26),2) -> 82057.83 | AN26: =DealsRawTable[[#This Row],[Validated_Annual_Final_Price]]*DealsRawTable[[#This Row],[Contract_Years]] -> 82057.83 | AO26: =DealsRawTable[[#This Row],[Validated_Annual_Final_Price]]-DealsRawTable[[#This Row],[Cost_to_Serve]] -> 44533.199 | AP26: =DealsRawTable[[#This Row],[Validated_Grossprofit]]/DealsRawTable[[#This Row],[Validated_Annual_Final_Price]] -> 0.54270506 | AQ26: 82057.83 | AR26: 82057.83 | AS26: 44533.199 | AT26: 0.54270506 | AU26: =IF(W26<=0.05,"0–5%", IF(W26<=0.1,"5–10%", IF(W26<=0.15,"10–15%", IF(W26<=0.2,"15–20%", IF(W26<=0.25,"20–25%", IF(W26<=0.3,"25–30%","Above 30%")))))) -> 15–20% | AV26: 108
A27: D00029 | B27: 45796 | C27: C0007 | D27: FIN-0007 | E27: CT00017 | F27: Technology | G27: Financial Services | H27: Northeast | I27: Northeast Commercial | J27: Mid-Market | K27: No | L27: 43160 | M27: 47 | N27: Nexus Enterprise Suite | O27: New Business | Q27: 3 | R27: 133 | S27: M. Johnson | T27: 362900.54 | U27: =T27*DealsRawTable[[#This Row],[Contract_Years]] -> 1088701.6 | V27: 0.147 | W27: 0.112 | X27: -0.14 | Y27: Strategic logo opportunity | Z27: Pricing Analyst | AA27: 322206.16 | AB27: =DealsRawTable[[#This Row],[Final_Price_ACV]]*DealsRawTable[[#This Row],[Contract_Years]] -> 966618.47 | AC27: 137627.51 | AD27: 184578.65 | AE27: 0.57285884 | AF27: Lost | AI27: No | AJ27: 0 | AK27: 0 | AL27: First purchase under this contract | AM27: =ROUND(T27*(1-W27),2) -> 322255.68 | AN27: =DealsRawTable[[#This Row],[Validated_Annual_Final_Price]]*DealsRawTable[[#This Row],[Contract_Years]] -> 966767.04 | AO27: =DealsRawTable[[#This Row],[Validated_Annual_Final_Price]]-DealsRawTable[[#This Row],[Cost_to_Serve]] -> 184628.17 | AP27: =DealsRawTable[[#This Row],[Validated_Grossprofit]]/DealsRawTable[[#This Row],[Validated_Annual_Final_Price]] -> 0.57292448 | AQ27: 0 | AR27: 0 | AS27: 0 | AT27: 0 | AU27: =IF(W27<=0.05,"0–5%", IF(W27<=0.1,"5–10%", IF(W27<=0.15,"10–15%", IF(W27<=0.2,"15–20%", IF(W27<=0.25,"20–25%", IF(W27<=0.3,"25–30%","Above 30%")))))) -> 10–15% | AV27: 113
A28: D00030 | B28: 45719 | C28: C0008 | D28: TEC-0008 | E28: CT00018 | F28: Legal | G28: Technology | H28: South | I28: South Enterprise | J28: Enterprise | K28: Yes | L28: 45536 | M28: 71 | N28: Nexus Compliance | O28: New Business | Q28: 1 | R28: 796 | S28: T. Brooks | T28: 181007.6 | U28: =T28*DealsRawTable[[#This Row],[Contract_Years]] -> 181007.6 | V28: 0.25 | W28: 0.234 | X28: 0.134 | Y28: Procurement requirement | Z28: Business Manager | AA28: 138635.96 | AB28: =DealsRawTable[[#This Row],[Final_Price_ACV]]*DealsRawTable[[#This Row],[Contract_Years]] -> 138635.96 | AC28: 66961.706 | AD28: 71674.258 | AE28: 0.51699614 | AF28: Lost | AI28: No | AJ28: 0 | AK28: 0 | AL28: First purchase under this contract | AM28: =ROUND(T28*(1-W28),2) -> 138651.82 | AN28: =DealsRawTable[[#This Row],[Validated_Annual_Final_Price]]*DealsRawTable[[#This Row],[Contract_Years]] -> 138651.82 | AO28: =DealsRawTable[[#This Row],[Validated_Annual_Final_Price]]-DealsRawTable[[#This Row],[Cost_to_Serve]] -> 71690.114 | AP28: =DealsRawTable[[#This Row],[Validated_Grossprofit]]/DealsRawTable[[#This Row],[Validated_Annual_Final_Price]] -> 0.51705137 | AQ28: 0 | AR28: 0 | AS28: 0 | AT28: 0 | AU28: =IF(W28<=0.05,"0–5%", IF(W28<=0.1,"5–10%", IF(W28<=0.15,"10–15%", IF(W28<=0.2,"15–20%", IF(W28<=0.25,"20–25%", IF(W28<=0.3,"25–30%","Above 30%")))))) -> 20–25% | AV28: 29
A29: D00031 | B29: 45830 | C29: C0008 | D29: TEC-0008 | E29: CT00019 | F29: Finance | G29: Technology | H29: South | I29: South Enterprise | J29: Enterprise | K29: Yes | L29: 45536 | M29: 71 | N29: Nexus Analytics | O29: New Business | Q29: 1 | R29: 1345 | S29: M. Johnson | T29: 237976.42 | U29: =T29*DealsRawTable[[#This Row],[Contract_Years]] -> 237976.42 | V29: 0.105 | W29: 0.1 | X29: 0.07 | Y29: Expansion opportunity | Z29: Pricing Analyst | AA29: 214135.78 | AB29: =DealsRawTable[[#This Row],[Final_Price_ACV]]*DealsRawTable[[#This Row],[Contract_Years]] -> 214135.78 | AC29: 84085.734 | AD29: 130050.05 | AE29: 0.60732515 | AF29: Lost | AI29: No | AJ29: 0 | AK29: 0 | AL29: First purchase under this contract | AM29: =ROUND(T29*(1-W29),2) -> 214178.78 | AN29: =DealsRawTable[[#This Row],[Validated_Annual_Final_Price]]*DealsRawTable[[#This Row],[Contract_Years]] -> 214178.78 | AO29: =DealsRawTable[[#This Row],[Validated_Annual_Final_Price]]-DealsRawTable[[#This Row],[Cost_to_Serve]] -> 130093.05 | AP29: =DealsRawTable[[#This Row],[Validated_Grossprofit]]/DealsRawTable[[#This Row],[Validated_Annual_Final_Price]] -> 0.60740399 | AQ29: 0 | AR29: 0 | AS29: 0 | AT29: 0 | AU29: =IF(W29<=0.05,"0–5%", IF(W29<=0.1,"5–10%", IF(W29<=0.15,"10–15%", IF(W29<=0.2,"15–20%", IF(W29<=0.25,"20–25%", IF(W29<=0.3,"25–30%","Above 30%")))))) -> 5–10% | AV29: 116
A30: D00032 | B30: 45580 | C30: C0009 | D30: MAN-0009 | E30: CT00020 | F30: Sales | G30: Manufacturing | H30: Midwest | I30: Midwest Commercial | J30: SMB | K30: No | L30: 44682 | M30: 38 | N30: Nexus AI Assistant | O30: New Business | Q30: 1 | R30: 75 | S30: R. Singh | T30: 41655.051 | U30: =T30*DealsRawTable[[#This Row],[Contract_Years]] -> 41655.051 | V30: 0.226 | W30: 0.184 | X30: -0.117 | Y30: Procurement requirement | Z30: Pricing Analyst | AA30: 33993.638 | AB30: =DealsRawTable[[#This Row],[Final_Price_ACV]]*DealsRawTable[[#This Row],[Contract_Years]] -> 33993.638 | AC30: 17884.639 | AD30: 16109 | AE30: 0.47388278 | AF30: Lost | AI30: No | AJ30: 0 | AK30: 0 | AL30: First purchase under this contract | AM30: =ROUND(T30*(1-W30),2) -> 33990.52 | AN30: =DealsRawTable[[#This Row],[Validated_Annual_Final_Price]]*DealsRawTable[[#This Row],[Contract_Years]] -> 33990.52 | AO30: =DealsRawTable[[#This Row],[Validated_Annual_Final_Price]]-DealsRawTable[[#This Row],[Cost_to_Serve]] -> 16105.881 | AP30: =DealsRawTable[[#This Row],[Validated_Grossprofit]]/DealsRawTable[[#This Row],[Validated_Annual_Final_Price]] -> 0.47383451 | AQ30: 0 | AR30: 0 | AS30: 0 | AT30: 0 | AU30: =IF(W30<=0.05,"0–5%", IF(W30<=0.1,"5–10%", IF(W30<=0.15,"10–15%", IF(W30<=0.2,"15–20%", IF(W30<=0.25,"20–25%", IF(W30<=0.3,"25–30%","Above 30%")))))) -> 15–20% | AV30: 108
A31: D00033 | B31: 45882 | C31: C0010 | D31: LEG-0010 | E31: CT00021 | F31: Legal | G31: Legal | H31: West | I31: West Commercial | J31: Mid-Market | K31: No | L31: 44348 | M31: 59 | N31: Nexus Analytics | O31: Renewal | Q31: 2 | R31: 207 | S31: D. Chen | T31: 139960.13 | U31: =T31*DealsRawTable[[#This Row],[Contract_Years]] -> 279920.25 | V31: 0.204 | W31: 0.156 | X31: -0.001 | Y31: Renewal retention risk | Z31: Pricing Analyst | AA31: 118066.05 | AB31: =DealsRawTable[[#This Row],[Final_Price_ACV]]*DealsRawTable[[#This Row],[Contract_Years]] -> 236132.1 | AC31: 43010.71 | AD31: 75055.341 | AE31: 0.63570637 | AF31: Lost | AG31: No | AI31: No | AJ31: 0 | AK31: 0 | AL31: Renewal of existing active contract | AM31: =ROUND(T31*(1-W31),2) -> 118126.35 | AN31: =DealsRawTable[[#This Row],[Validated_Annual_Final_Price]]*DealsRawTable[[#This Row],[Contract_Years]] -> 236252.7 | AO31: =DealsRawTable[[#This Row],[Validated_Annual_Final_Price]]-DealsRawTable[[#This Row],[Cost_to_Serve]] -> 75115.64 | AP31: =DealsRawTable[[#This Row],[Validated_Grossprofit]]/DealsRawTable[[#This Row],[Validated_Annual_Final_Price]] -> 0.63589233 | AQ31: 0 | AR31: 0 | AS31: 0 | AT31: 0 | AU31: =IF(W31<=0.05,"0–5%", IF(W31<=0.1,"5–10%", IF(W31<=0.15,"10–15%", IF(W31<=0.2,"15–20%", IF(W31<=0.25,"20–25%", IF(W31<=0.3,"25–30%","Above 30%")))))) -> 15–20% | AV31: 108
A32: D00034 | B32: 45298 | C32: C0011 | D32: TEC-0011 | E32: CT00022 | F32: Sales | G32: Technology | H32: Midwest | I32: Midwest Enterprise | J32: Enterprise | K32: Yes | L32: 44197 | M32: 45 | N32: Nexus Compliance | O32: New Business | Q32: 1 | R32: 628 | S32: A. Patel | T32: 253577.77 | U32: =T32*DealsRawTable[[#This Row],[Contract_Years]] -> 253577.77 | V32: 0.171 | W32: 0.134 | X32: 0.044 | Y32: Volume purchase | Z32: Pricing Analyst | AA32: 219611.38 | AB32: =DealsRawTable[[#This Row],[Final_Price_ACV]]*DealsRawTable[[#This Row],[Contract_Years]] -> 219611.38 | AC32: 106942.15 | AD32: 112669.23 | AE32: 0.51303911 | AF32: Lost | AI32: No | AJ32: 0 | AK32: 0 | AL32: First purchase under this contract | AM32: =ROUND(T32*(1-W32),2) -> 219598.35 | AN32: =DealsRawTable[[#This Row],[Validated_Annual_Final_Price]]*DealsRawTable[[#This Row],[Contract_Years]] -> 219598.35 | AO32: =DealsRawTable[[#This Row],[Validated_Annual_Final_Price]]-DealsRawTable[[#This Row],[Cost_to_Serve]] -> 112656.2 | AP32: =DealsRawTable[[#This Row],[Validated_Grossprofit]]/DealsRawTable[[#This Row],[Validated_Annual_Final_Price]] -> 0.51301022 | AQ32: 0 | AR32: 0 | AS32: 0 | AT32: 0 | AU32: =IF(W32<=0.05,"0–5%", IF(W32<=0.1,"5–10%", IF(W32<=0.15,"10–15%", IF(W32<=0.2,"15–20%", IF(W32<=0.25,"20–25%", IF(W32<=0.3,"25–30%","Above 30%")))))) -> 10–15% | AV32: 113
A33: D00035 | B33: 45386 | C33: C0011 | D33: TEC-0011 | E33: CT00023 | F33: Corporate | G33: Technology | H33: Midwest | I33: Midwest Enterprise | J33: Enterprise | K33: Yes | L33: 44197 | M33: 45 | N33: Nexus Compliance | O33: New Business | Q33: 3 | R33: 1885 | S33: S. Rivera | T33: 468080.85 | U33: =T33*DealsRawTable[[#This Row],[Contract_Years]] -> 1404242.6 | V33: 0.184 | W33: 0.152 | X33: -0.18 | Y33: Strategic logo opportunity | Z33: Pricing Analyst | AA33: 396827.15 | AB33: =DealsRawTable[[#This Row],[Final_Price_ACV]]*DealsRawTable[[#This Row],[Contract_Years]] -> 1190481.4 | AC33: 177287.52 | AD33: 219539.63 | AE33: 0.55323742 | AF33: Lost | AI33: No | AJ33: 0 | AK33: 0 | AL33: First purchase under this contract | AM33: =ROUND(T33*(1-W33),2) -> 396932.56 | AN33: =DealsRawTable[[#This Row],[Validated_Annual_Final_Price]]*DealsRawTable[[#This Row],[Contract_Years]] -> 1190797.7 | AO33: =DealsRawTable[[#This Row],[Validated_Annual_Final_Price]]-DealsRawTable[[#This Row],[Cost_to_Serve]] -> 219645.04 | AP33: =DealsRawTable[[#This Row],[Validated_Grossprofit]]/DealsRawTable[[#This Row],[Validated_Annual_Final_Price]] -> 0.55335606 | AQ33: 0 | AR33: 0 | AS33: 0 | AT33: 0 | AU33: =IF(W33<=0.05,"0–5%", IF(W33<=0.1,"5–10%", IF(W33<=0.15,"10–15%", IF(W33<=0.2,"15–20%", IF(W33<=0.25,"20–25%", IF(W33<=0.3,"25–30%","Above 30%")))))) -> 15–20% | AV33: 108
A34: D00036 | B34: 45719 | C34: C0011 | D34: TEC-0011 | E34: CT00023 | F34: Corporate | G34: Technology | H34: Midwest | I34: Midwest Enterprise | J34: Enterprise | K34: Yes | L34: 44197 | M34: 45 | N34: Nexus Compliance | O34: Win-back | Q34: 3 | R34: 1885 | S34: A. Patel | T34: 468080.85 | U34: =T34*DealsRawTable[[#This Row],[Contract_Years]] -> 1404242.6 | V34: 0.182 | W34: 0.171 | X34: -0.135 | Y34: Renewal retention risk | Z34: Pricing Analyst | AA34: 387889.1 | AB34: =DealsRawTable[[#This Row],[Final_Price_ACV]]*DealsRawTable[[#This Row],[Contract_Years]] -> 1163667.3 | AC34: 167433.57 | AD34: 220455.53 | AE34: 0.5683468 | AF34: Won | AI34: Yes | AJ34: 387889.1 | AK34: 220455.53 | AL34: Customer returned after prior lost initial opportunity | AM34: =ROUND(T34*(1-W34),2) -> 388039.03 | AN34: =DealsRawTable[[#This Row],[Validated_Annual_Final_Price]]*DealsRawTable[[#This Row],[Contract_Years]] -> 1164117.1 | AO34: =DealsRawTable[[#This Row],[Validated_Annual_Final_Price]]-DealsRawTable[[#This Row],[Cost_to_Serve]] -> 220605.46 | AP34: =DealsRawTable[[#This Row],[Validated_Grossprofit]]/DealsRawTable[[#This Row],[Validated_Annual_Final_Price]] -> 0.56851357 | AQ34: 388039.03 | AR34: 1164117.1 | AS34: 220605.46 | AT34: 0.56851357 | AU34: =IF(W34<=0.05,"0–5%", IF(W34<=0.1,"5–10%", IF(W34<=0.15,"10–15%", IF(W34<=0.2,"15–20%", IF(W34<=0.25,"20–25%", IF(W34<=0.3,"25–30%","Above 30%")))))) -> 15–20% | AV34: 108
A35: D00037 | B35: 45776 | C35: C0012 | D35: TEC-0012 | E35: CT00024 | F35: Operations | G35: Technology | H35: Midwest | I35: Midwest Commercial | J35: Mid-Market | K35: No | L35: 44531 | M35: 69 | N35: Nexus Compliance | O35: New Business | Q35: 1 | R35: 338 | S35: M. Johnson | T35: 173097.35 | U35: =T35*DealsRawTable[[#This Row],[Contract_Years]] -> 173097.35 | V35: 0.124 | W35: 0.079 | X35: -0.048 | Y35: Expansion opportunity | Z35: Sales Manager | AA35: 159491.64 | AB35: =DealsRawTable[[#This Row],[Final_Price_ACV]]*DealsRawTable[[#This Row],[Contract_Years]] -> 159491.64 | AC35: 61793.253 | AD35: 97698.391 | AE35: 0.61256119 | AF35: Won | AI35: No | AJ35: 159491.64 | AK35: 97698.391 | AL35: First purchase under this contract | AM35: =ROUND(T35*(1-W35),2) -> 159422.66 | AN35: =DealsRawTable[[#This Row],[Validated_Annual_Final_Price]]*DealsRawTable[[#This Row],[Contract_Years]] -> 159422.66 | AO35: =DealsRawTable[[#This Row],[Validated_Annual_Final_Price]]-DealsRawTable[[#This Row],[Cost_to_Serve]] -> 97629.407 | AP35: =DealsRawTable[[#This Row],[Validated_Grossprofit]]/DealsRawTable[[#This Row],[Validated_Annual_Final_Price]] -> 0.61239354 | AQ35: 159422.66 | AR35: 159422.66 | AS35: 97629.407 | AT35: 0.61239354 | AU35: =IF(W35<=0.05,"0–5%", IF(W35<=0.1,"5–10%", IF(W35<=0.15,"10–15%", IF(W35<=0.2,"15–20%", IF(W35<=0.25,"20–25%", IF(W35<=0.3,"25–30%","Above 30%")))))) -> 5–10% | AV35: 116
A36: D00038 | B36: 45702 | C36: C0012 | D36: TEC-0012 | E36: CT00025 | F36: Legal | G36: Technology | H36: Midwest | I36: Midwest Commercial | J36: Mid-Market | K36: No | L36: 44531 | M36: 69 | N36: Nexus Analytics | O36: Renewal | Q36: 3 | R36: 213 | S36: A. Patel | T36: 120002.86 | U36: =T36*DealsRawTable[[#This Row],[Contract_Years]] -> 360008.57 | V36: 0.069 | W36: 0.056 | X36: -0.018 | Y36: Budget constraint | Z36: Sales Manager | AA36: 113266.12 | AB36: =DealsRawTable[[#This Row],[Final_Price_ACV]]*DealsRawTable[[#This Row],[Contract_Years]] -> 339798.36 | AC36: 38550.371 | AD36: 74715.749 | AE36: 0.65964782 | AF36: Won | AG36: Yes | AI36: No | AJ36: 113266.12 | AK36: 74715.749 | AL36: Renewal of existing active contract | AM36: =ROUND(T36*(1-W36),2) -> 113282.7 | AN36: =DealsRawTable[[#This Row],[Validated_Annual_Final_Price]]*DealsRawTable[[#This Row],[Contract_Years]] -> 339848.1 | AO36: =DealsRawTable[[#This Row],[Validated_Annual_Final_Price]]-DealsRawTable[[#This Row],[Cost_to_Serve]] -> 74732.329 | AP36: =DealsRawTable[[#This Row],[Validated_Grossprofit]]/DealsRawTable[[#This Row],[Validated_Annual_Final_Price]] -> 0.65969763 | AQ36: 113282.7 | AR36: 339848.1 | AS36: 74732.329 | AT36: 0.65969763 | AU36: =IF(W36<=0.05,"0–5%", IF(W36<=0.1,"5–10%", IF(W36<=0.15,"10–15%", IF(W36<=0.2,"15–20%", IF(W36<=0.25,"20–25%", IF(W36<=0.3,"25–30%","Above 30%")))))) -> 5–10% | AV36: 116
A37: D00039 | B37: 45551 | C37: C0013 | D37: FIN-0013 | E37: CT00027 | F37: Finance | G37: Financial Services | H37: West | I37: West Commercial | J37: Mid-Market | K37: No | L37: 44531 | M37: 67 | N37: Nexus AI Assistant | O37: Renewal | Q37: 1 | R37: 280 | S37: T. Brooks | T37: 55186.784 | U37: =T37*DealsRawTable[[#This Row],[Contract_Years]] -> 55186.784 | V37: 0.2 | W37: 0.178 | X37: -0.073 | Y37: Multi-year commitment | Z37: Pricing Analyst | AA37: 45368.135 | AB37: =DealsRawTable[[#This Row],[Final_Price_ACV]]*DealsRawTable[[#This Row],[Contract_Years]] -> 45368.135 | AC37: 21810.707 | AD37: 23557.427 | AE37: 0.51925052 | AF37: Won | AG37: Yes | AI37: No | AJ37: 45368.135 | AK37: 23557.427 | AL37: Renewal of existing active contract | AM37: =ROUND(T37*(1-W37),2) -> 45363.54 | AN37: =DealsRawTable[[#This Row],[Validated_Annual_Final_Price]]*DealsRawTable[[#This Row],[Contract_Years]] -> 45363.54 | AO37: =DealsRawTable[[#This Row],[Validated_Annual_Final_Price]]-DealsRawTable[[#This Row],[Cost_to_Serve]] -> 23552.833 | AP37: =DealsRawTable[[#This Row],[Validated_Grossprofit]]/DealsRawTable[[#This Row],[Validated_Annual_Final_Price]] -> 0.51920182 | AQ37: 45363.54 | AR37: 45363.54 | AS37: 23552.833 | AT37: 0.51920182 | AU37: =IF(W37<=0.05,"0–5%", IF(W37<=0.1,"5–10%", IF(W37<=0.15,"10–15%", IF(W37<=0.2,"15–20%", IF(W37<=0.25,"20–25%", IF(W37<=0.3,"25–30%","Above 30%")))))) -> 15–20% | AV37: 108
A38: D00040 | B38: 45750 | C38: C0013 | D38: FIN-0013 | E38: CT00027 | F38: Finance | G38: Financial Services | H38: West | I38: West Commercial | J38: Mid-Market | K38: No | L38: 44531 | M38: 67 | N38: Nexus AI Assistant | O38: Expansion | P38: Storage / Usage Expansion | Q38: 1 | R38: 397 | S38: T. Brooks | T38: 66130.911 | U38: =T38*DealsRawTable[[#This Row],[Contract_Years]] -> 66130.911 | V38: 0.187 | W38: 0.165 | X38: -0.017 | Y38: Expansion opportunity | Z38: Pricing Analyst | AA38: 55225.688 | AB38: =DealsRawTable[[#This Row],[Final_Price_ACV]]*DealsRawTable[[#This Row],[Contract_Years]] -> 55225.688 | AC38: 25358.411 | AD38: 29867.278 | AE38: 0.54082219 | AF38: Won | AH38: Yes | AI38: No | AJ38: 55225.688 | AK38: 29867.278 | AL38: Expansion allowed because contract was active | AM38: =ROUND(T38*(1-W38),2) -> 55219.31 | AN38: =DealsRawTable[[#This Row],[Validated_Annual_Final_Price]]*DealsRawTable[[#This Row],[Contract_Years]] -> 55219.31 | AO38: =DealsRawTable[[#This Row],[Validated_Annual_Final_Price]]-DealsRawTable[[#This Row],[Cost_to_Serve]] -> 29860.899 | AP38: =DealsRawTable[[#This Row],[Validated_Grossprofit]]/DealsRawTable[[#This Row],[Validated_Annual_Final_Price]] -> 0.54076915 | AQ38: 55219.31 | AR38: 55219.31 | AS38: 29860.899 | AT38: 0.54076915 | AU38: =IF(W38<=0.05,"0–5%", IF(W38<=0.1,"5–10%", IF(W38<=0.15,"10–15%", IF(W38<=0.2,"15–20%", IF(W38<=0.25,"20–25%", IF(W38<=0.3,"25–30%","Above 30%")))))) -> 15–20% | AV38: 108
A39: D00041 | B39: 45916 | C39: C0013 | D39: FIN-0013 | E39: CT00027 | F39: Finance | G39: Financial Services | H39: West | I39: West Commercial | J39: Mid-Market | K39: No | L39: 44531 | M39: 67 | N39: Nexus AI Assistant | O39: Renewal | Q39: 1 | R39: 397 | S39: A. Patel | T39: 67469.034 | U39: =T39*DealsRawTable[[#This Row],[Contract_Years]] -> 67469.034 | V39: 0.077 | W39: 0.034 | X39: -0.029 | Y39: Budget constraint | Z39: Sales Manager | AA39: 65189.491 | AB39: =DealsRawTable[[#This Row],[Final_Price_ACV]]*DealsRawTable[[#This Row],[Contract_Years]] -> 65189.491 | AC39: 25848.65 | AD39: 39340.84 | AE39: 0.6034844 | AF39: Won | AG39: Yes | AI39: No | AJ39: 65189.491 | AK39: 39340.84 | AL39: Renewal of existing active contract | AM39: =ROUND(T39*(1-W39),2) -> 65175.09 | AN39: =DealsRawTable[[#This Row],[Validated_Annual_Final_Price]]*DealsRawTable[[#This Row],[Contract_Years]] -> 65175.09 | AO39: =DealsRawTable[[#This Row],[Validated_Annual_Final_Price]]-DealsRawTable[[#This Row],[Cost_to_Serve]] -> 39326.44 | AP39: =DealsRawTable[[#This Row],[Validated_Grossprofit]]/DealsRawTable[[#This Row],[Validated_Annual_Final_Price]] -> 0.60339678 | AQ39: 65175.09 | AR39: 65175.09 | AS39: 39326.44 | AT39: 0.60339678 | AU39: =IF(W39<=0.05,"0–5%", IF(W39<=0.1,"5–10%", IF(W39<=0.15,"10–15%", IF(W39<=0.2,"15–20%", IF(W39<=0.25,"20–25%", IF(W39<=0.3,"25–30%","Above 30%")))))) -> 0–5% | AV39: 55
A40: D00042 | B40: 45719 | C40: C0013 | D40: FIN-0013 | E40: CT00028 | F40: Technology | G40: Financial Services | H40: West | I40: West Commercial | J40: Mid-Market | K40: No | L40: 44531 | M40: 67 | N40: Nexus Analytics | O40: New Business | Q40: 3 | R40: 115 | S40: S. Rivera | T40: 102198.77 | U40: =T40*DealsRawTable[[#This Row],[Contract_Years]] -> 306596.3 | V40: 0.069 | W40: 0.051 | X40: 0.031 | Y40: Verified competitor pressure | Z40: Sales Manager | AA40: 97031.658 | AB40: =DealsRawTable[[#This Row],[Final_Price_ACV]]*DealsRawTable[[#This Row],[Contract_Years]] -> 291094.97 | AC40: 35647.422 | AD40: 61384.236 | AE40: 0.6326207 | AF40: Won | AI40: No | AJ40: 97031.658 | AK40: 61384.236 | AL40: First purchase under this contract | AM40: =ROUND(T40*(1-W40),2) -> 96986.63 | AN40: =DealsRawTable[[#This Row],[Validated_Annual_Final_Price]]*DealsRawTable[[#This Row],[Contract_Years]] -> 290959.89 | AO40: =DealsRawTable[[#This Row],[Validated_Annual_Final_Price]]-DealsRawTable[[#This Row],[Cost_to_Serve]] -> 61339.208 | AP40: =DealsRawTable[[#This Row],[Validated_Grossprofit]]/DealsRawTable[[#This Row],[Validated_Annual_Final_Price]] -> 0.63245014 | AQ40: 96986.63 | AR40: 290959.89 | AS40: 61339.208 | AT40: 0.63245014 | AU40: =IF(W40<=0.05,"0–5%", IF(W40<=0.1,"5–10%", IF(W40<=0.15,"10–15%", IF(W40<=0.2,"15–20%", IF(W40<=0.25,"20–25%", IF(W40<=0.3,"25–30%","Above 30%")))))) -> 5–10% | AV40: 116
A41: D00043 | B41: 45343 | C41: C0013 | D41: FIN-0013 | E41: CT00029 | F41: Operations | G41: Financial Services | H41: West | I41: West Commercial | J41: Mid-Market | K41: No | L41: 44531 | M41: 67 | N41: Nexus Analytics | O41: Renewal | Q41: 1 | R41: 264 | S41: T. Brooks | T41: 109848.93 | U41: =T41*DealsRawTable[[#This Row],[Contract_Years]] -> 109848.93 | V41: 0.2 | W41: 0.197 | X41: -0.094 | Y41: Budget constraint | Z41: Pricing Analyst | AA41: 88180.622 | AB41: =DealsRawTable[[#This Row],[Final_Price_ACV]]*DealsRawTable[[#This Row],[Contract_Years]] -> 88180.622 | AC41: 30477.677 | AD41: 57702.944 | AE41: 0.65437217 | AF41: Won | AG41: Yes | AI41: No | AJ41: 88180.622 | AK41: 57702.944 | AL41: Renewal of existing active contract | AM41: =ROUND(T41*(1-W41),2) -> 88208.69 | AN41: =DealsRawTable[[#This Row],[Validated_Annual_Final_Price]]*DealsRawTable[[#This Row],[Contract_Years]] -> 88208.69 | AO41: =DealsRawTable[[#This Row],[Validated_Annual_Final_Price]]-DealsRawTable[[#This Row],[Cost_to_Serve]] -> 57731.013 | AP41: =DealsRawTable[[#This Row],[Validated_Grossprofit]]/DealsRawTable[[#This Row],[Validated_Annual_Final_Price]] -> 0.65448215 | AQ41: 88208.69 | AR41: 88208.69 | AS41: 57731.013 | AT41: 0.65448215 | AU41: =IF(W41<=0.05,"0–5%", IF(W41<=0.1,"5–10%", IF(W41<=0.15,"10–15%", IF(W41<=0.2,"15–20%", IF(W41<=0.25,"20–25%", IF(W41<=0.3,"25–30%","Above 30%")))))) -> 15–20% | AV41: 108
